<?xml version="1.0"?>
<robot name="mini_humanoid">
  <material name="white"> <color rgba="1 1 1 1"/> </material>
  <material name="black"> <color rgba="0 0 0 1"/> </material>

  <link name="torso_link">
    <visual> <geometry><box size="0.2 0.1 0.4"/></geometry> <material name="white"/> </visual>
    <collision> <geometry><box size="0.2 0.1 0.4"/></geometry> </collision>
    <inertial> <mass value="10"/> <origin xyz="0 0 0.2"/> <inertia ixx="1" ixy="0" ixz="0" iyy="1" iyz="0" izz="1"/> </inertial>
  </link>

  <joint name="neck_joint" type="revolute">
    <parent link="torso_link"/>
    <child link="head_link"/>
    <origin xyz="0 0 0.25"/>
    <axis xyz="0 0 1"/>
    <limit lower="-1.57" upper="1.57" effort="10" velocity="1"/>
  </joint>

  <link name="head_link">
    <visual> <geometry><sphere radius="0.1"/></geometry> <material name="black"/> </visual>
    <collision> <geometry><sphere radius="0.1"/></geometry> </collision>
    <inertial> <mass value="1"/> <origin xyz="0 0 0"/> <inertia ixx="0.1" ixy="0" ixz="0" iyy="0.1" iyz="0" izz="0.1"/> </inertial>
  </link>

  <joint name="right_shoulder_joint" type="revolute">
    <parent link="torso_link"/>
    <child link="right_arm_link"/>
    <origin xyz="0 0.15 0.15"/>
    <axis xyz="1 0 0"/>
    <limit lower="-1.57" upper="1.57" effort="10" velocity="1"/>
  </joint>

  <link name="right_arm_link">
    <visual> <geometry><cylinder radius="0.03" length="0.3"/></geometry> <origin xyz="0 0 -0.15"/> <material name="white"/> </visual>
    <collision> <geometry><cylinder radius="0.03" length="0.3"/></geometry> <origin xyz="0 0 -0.15"/> </collision>
    <inertial> <mass value="0.5"/> <origin xyz="0 0 -0.15"/> <inertia ixx="0.05" ixy="0" ixz="0" iyy="0.05" iyz="0" izz="0.05"/> </inertial>
  </link>

</robot>
