<?xml version="1.0"?>
<robot name="simple_humanoid">

  <material name="blue">
    <color rgba="0 0 1 1"/>
  </material>
  <material name="red">
    <color rgba="1 0 0 1"/>
  </material>

  <!-- Base Link (Torso) -->
  <link name="base_link">
    <visual>
      <geometry>
        <box size="0.2 0.1 0.3"/>
      </geometry>
      <material name="red"/>
    </visual>
    <collision>
      <geometry>
        <box size="0.2 0.1 0.3"/>
      </geometry>
    </collision>
    <inertial>
      <mass value="5.0"/>
      <origin xyz="0 0 0.15"/>
      <inertia ixx="0.1" ixy="0" ixz="0" iyy="0.1" iyz="0" izz="0.1"/>
    </inertial>
  </link>

  <!-- Shoulder Joint -->
  <joint name="shoulder_joint" type="revolute">
    <parent link="base_link"/>
    <child link="upper_arm_link"/>
    <origin xyz="0 0.1 0.25" rpy="0 0 0"/> <!-- Attaches to side of torso -->
    <axis xyz="1 0 0"/> <!-- Rotates around X-axis -->
    <limit lower="-1.57" upper="1.57" effort="100" velocity="10"/>
  </joint>

  <!-- Upper Arm Link -->
  <link name="upper_arm_link">
    <visual>
      <geometry>
        <cylinder radius="0.03" length="0.2"/>
      </geometry>
      <origin xyz="0 0 -0.1"/> <!-- Center cylinder along Y, extend down -->
      <material name="blue"/>
    </visual>
    <collision>
      <geometry>
        <cylinder radius="0.03" length="0.2"/>
      </geometry>
      <origin xyz="0 0 -0.1"/>
    </collision>
    <inertial>
      <mass value="0.5"/>
      <origin xyz="0 0 -0.1"/>
      <inertia ixx="0.01" ixy="0" ixz="0" iyy="0.01" iyz="0" izz="0.01"/>
    </inertial>
  </link>

  <!-- Transmission for Shoulder Joint -->
  <transmission name="shoulder_trans">
    <type>transmission_interface/SimpleTransmission</type>
    <joint name="shoulder_joint">
      <hardwareInterface>hardware_interface/PositionJointInterface</hardwareInterface>
    </joint>
    <actuator name="shoulder_motor">
      <mechanicalReduction>1</mechanicalReduction>
      <hardwareInterface>hardware_interface/PositionJointInterface</hardwareInterface>
    </actuator>
  </transmission>

</robot>
